<?xml version="1.0" encoding="UTF-8"?>
<testsuite name="tests.technix.TechnixTests-20220404141004" tests="6" file="tests/technix.py" time="44.006" timestamp="2022-04-04T14:11:01" failures="5" errors="1" skipped="0">
	<testcase classname="tests.technix.TechnixTests" name="test_WHEN_set_inhibit_to_active_THEN_inhibit_is_active" time="7.229" timestamp="2022-04-04T14:10:34" file="tests\technix.py" line="69">
		<failure type="AssertionError" message="Exception date time: 2022-04-04 14:10:34.494093
PV TE:NDW1799:TECHNIX_01:INHIBIT:SP does not exist"><![CDATA[Traceback (most recent call last):
  File "C:\Instrument\Apps\EPICS\support\IocTestFramework\master\utils\testing.py", line 148, in wrapper
    return func(*args, **kwargs)
  File "C:\Instrument\Apps\EPICS\support\technix\master\system_tests\tests\technix.py", line 71, in test_WHEN_set_inhibit_to_active_THEN_inhibit_is_active
    _set_inhibit(self.ca, "ACTIVE")
  File "C:\Instrument\Apps\EPICS\support\technix\master\system_tests\tests\technix.py", line 31, in _set_inhibit
    ca.set_pv_value("INHIBIT:SP", mode)
  File "C:\Instrument\Apps\EPICS\support\IocTestFramework\master\utils\channel_access.py", line 120, in set_pv_value
    self.assert_that_pv_exists(pv)
  File "C:\Instrument\Apps\EPICS\support\IocTestFramework\master\utils\channel_access.py", line 484, in assert_that_pv_exists
    raise AssertionError("Exception date time: {time}\nPV {pv} does not exist".format(time=datetime.datetime.now(),pv=pv))
AssertionError: Exception date time: 2022-04-04 14:10:34.494093
PV TE:NDW1799:TECHNIX_01:INHIBIT:SP does not exist
]]></failure>
	</testcase>
	<testcase classname="tests.technix.TechnixTests" name="test_WHEN_set_inhibit_to_idle_THEN_inhibit_is_idle" time="7.211" timestamp="2022-04-04T14:10:41" file="tests\technix.py" line="64">
		<failure type="AssertionError" message="Exception date time: 2022-04-04 14:10:41.706784
PV TE:NDW1799:TECHNIX_01:INHIBIT:SP does not exist"><![CDATA[Traceback (most recent call last):
  File "C:\Instrument\Apps\EPICS\support\IocTestFramework\master\utils\testing.py", line 148, in wrapper
    return func(*args, **kwargs)
  File "C:\Instrument\Apps\EPICS\support\technix\master\system_tests\tests\technix.py", line 66, in test_WHEN_set_inhibit_to_idle_THEN_inhibit_is_idle
    _set_inhibit(self.ca, "IDLE")
  File "C:\Instrument\Apps\EPICS\support\technix\master\system_tests\tests\technix.py", line 31, in _set_inhibit
    ca.set_pv_value("INHIBIT:SP", mode)
  File "C:\Instrument\Apps\EPICS\support\IocTestFramework\master\utils\channel_access.py", line 120, in set_pv_value
    self.assert_that_pv_exists(pv)
  File "C:\Instrument\Apps\EPICS\support\IocTestFramework\master\utils\channel_access.py", line 484, in assert_that_pv_exists
    raise AssertionError("Exception date time: {time}\nPV {pv} does not exist".format(time=datetime.datetime.now(),pv=pv))
AssertionError: Exception date time: 2022-04-04 14:10:41.706784
PV TE:NDW1799:TECHNIX_01:INHIBIT:SP does not exist
]]></failure>
	</testcase>
	<testcase classname="tests.technix.TechnixTests" name="test_WHEN_set_local_mode_THEN_mode_is_local" time="7.226" timestamp="2022-04-04T14:10:48" file="tests\technix.py" line="54">
		<failure type="AssertionError" message="Exception date time: 2022-04-04 14:10:48.930664
PV TE:NDW1799:TECHNIX_01:LOCAL_MODE:SP does not exist"><![CDATA[Traceback (most recent call last):
  File "C:\Instrument\Apps\EPICS\support\IocTestFramework\master\utils\testing.py", line 148, in wrapper
    return func(*args, **kwargs)
  File "C:\Instrument\Apps\EPICS\support\technix\master\system_tests\tests\technix.py", line 56, in test_WHEN_set_local_mode_THEN_mode_is_local
    _set_local_mode(self.ca, "LOCAL")
  File "C:\Instrument\Apps\EPICS\support\technix\master\system_tests\tests\technix.py", line 27, in _set_local_mode
    ca.set_pv_value("LOCAL_MODE:SP", mode)
  File "C:\Instrument\Apps\EPICS\support\IocTestFramework\master\utils\channel_access.py", line 120, in set_pv_value
    self.assert_that_pv_exists(pv)
  File "C:\Instrument\Apps\EPICS\support\IocTestFramework\master\utils\channel_access.py", line 484, in assert_that_pv_exists
    raise AssertionError("Exception date time: {time}\nPV {pv} does not exist".format(time=datetime.datetime.now(),pv=pv))
AssertionError: Exception date time: 2022-04-04 14:10:48.930664
PV TE:NDW1799:TECHNIX_01:LOCAL_MODE:SP does not exist
]]></failure>
	</testcase>
	<testcase classname="tests.technix.TechnixTests" name="test_WHEN_set_remote_mode_THEN_mode_is_remote" time="7.215" timestamp="2022-04-04T14:10:56" file="tests\technix.py" line="59">
		<failure type="AssertionError" message="Exception date time: 2022-04-04 14:10:56.145383
PV TE:NDW1799:TECHNIX_01:LOCAL_MODE:SP does not exist"><![CDATA[Traceback (most recent call last):
  File "C:\Instrument\Apps\EPICS\support\IocTestFramework\master\utils\testing.py", line 148, in wrapper
    return func(*args, **kwargs)
  File "C:\Instrument\Apps\EPICS\support\technix\master\system_tests\tests\technix.py", line 61, in test_WHEN_set_remote_mode_THEN_mode_is_remote
    _set_local_mode(self.ca, "REMOTE")
  File "C:\Instrument\Apps\EPICS\support\technix\master\system_tests\tests\technix.py", line 27, in _set_local_mode
    ca.set_pv_value("LOCAL_MODE:SP", mode)
  File "C:\Instrument\Apps\EPICS\support\IocTestFramework\master\utils\channel_access.py", line 120, in set_pv_value
    self.assert_that_pv_exists(pv)
  File "C:\Instrument\Apps\EPICS\support\IocTestFramework\master\utils\channel_access.py", line 484, in assert_that_pv_exists
    raise AssertionError("Exception date time: {time}\nPV {pv} does not exist".format(time=datetime.datetime.now(),pv=pv))
AssertionError: Exception date time: 2022-04-04 14:10:56.145383
PV TE:NDW1799:TECHNIX_01:LOCAL_MODE:SP does not exist
]]></failure>
	</testcase>
	<testcase classname="tests.technix.TechnixTests" name="test_WHEN_set_voltage_THEN_get_voltage_back_correctly" time="5.122" timestamp="2022-04-04T14:11:01" file="tests\technix.py" line="46">
		<failure type="AssertionError" message="Exception date time: 2022-04-04 14:11:01.267351
Expected PV, 'TE:NDW1799:TECHNIX_01:VOLT' to have value '10' (type: 'int').
Final PV value was '0.0' (type: 'float')"><![CDATA[Traceback (most recent call last):
  File "C:\Instrument\Apps\EPICS\support\IocTestFramework\master\utils\testing.py", line 148, in wrapper
    return func(*args, **kwargs)
  File "C:\Instrument\Apps\EPICS\support\technix\master\system_tests\tests\technix.py", line 48, in test_WHEN_set_voltage_THEN_get_voltage_back_correctly
    self.ca.assert_setting_setpoint_sets_readback(10, "VOLT")
  File "C:\Instrument\Apps\EPICS\support\IocTestFramework\master\utils\channel_access.py", line 556, in assert_setting_setpoint_sets_readback
    self.assert_that_pv_is(readback_pv, expected_value, timeout=timeout)
  File "C:\Instrument\Apps\EPICS\support\IocTestFramework\master\utils\channel_access.py", line 271, in assert_that_pv_is
    return self.assert_that_pv_value_causes_func_to_return_true(
  File "C:\Instrument\Apps\EPICS\support\IocTestFramework\master\utils\channel_access.py", line 250, in assert_that_pv_value_causes_func_to_return_true
    raise AssertionError(err)
AssertionError: Exception date time: 2022-04-04 14:11:01.267351
Expected PV, 'TE:NDW1799:TECHNIX_01:VOLT' to have value '10' (type: 'int').
Final PV value was '0.0' (type: 'float')
]]></failure>
	</testcase>
	<testcase classname="tests.technix.TechnixTests" name="test_WHEN_set_current_THEN_get_current_back_correctly" time="10.004" timestamp="2022-04-04T14:10:27" file="tests\technix.py" line="50">
		<error type="UnableToConnectToPVException" message="Unable to connect to PV TE:NDW1799:TECHNIX_01:CURRENT: Connection timeout (event)"><![CDATA[Traceback (most recent call last):
  File "C:\Instrument\Apps\EPICS\support\IocTestFramework\master\utils\testing.py", line 148, in wrapper
    return func(*args, **kwargs)
  File "C:\Instrument\Apps\EPICS\support\technix\master\system_tests\tests\technix.py", line 52, in test_WHEN_set_current_THEN_get_current_back_correctly
    self.ca.assert_setting_setpoint_sets_readback(10, "CURRENT")
  File "C:\Instrument\Apps\EPICS\support\IocTestFramework\master\utils\channel_access.py", line 556, in assert_setting_setpoint_sets_readback
    self.assert_that_pv_is(readback_pv, expected_value, timeout=timeout)
  File "C:\Instrument\Apps\EPICS\support\IocTestFramework\master\utils\channel_access.py", line 271, in assert_that_pv_is
    return self.assert_that_pv_value_causes_func_to_return_true(
  File "C:\Instrument\Apps\EPICS\support\IocTestFramework\master\utils\channel_access.py", line 248, in assert_that_pv_value_causes_func_to_return_true
    err = self._wait_for_pv_lambda(partial(_wrapper, message), timeout)
  File "C:\Instrument\Apps\EPICS\support\IocTestFramework\master\utils\channel_access.py", line 213, in _wait_for_pv_lambda
    return wait_for_lambda()
  File "C:\Instrument\Apps\EPICS\support\IocTestFramework\master\utils\channel_access.py", line 230, in _wrapper
    value = self.get_pv_value(pv)
  File "C:\Instrument\Apps\EPICS\support\IocTestFramework\master\utils\channel_access.py", line 140, in get_pv_value
    return self.ca.get_pv_value(self.create_pv_with_prefix(pv))
  File "C:\Instrument\Apps\Python3\lib\site-packages\genie_python\genie_cachannel_wrapper.py", line 234, in get_pv_value
    chan = CaChannelWrapper.get_chan(name)
  File "C:\Instrument\Apps\Python3\lib\site-packages\genie_python\genie_cachannel_wrapper.py", line 212, in get_chan
    CaChannelWrapper.connect_to_pv(chan)
  File "C:\Instrument\Apps\Python3\lib\site-packages\genie_python\genie_cachannel_wrapper.py", line 333, in connect_to_pv
    raise UnableToConnectToPVException(ca_channel.name(), "Connection timeout (event)")
genie_python.channel_access_exceptions.UnableToConnectToPVException: Unable to connect to PV TE:NDW1799:TECHNIX_01:CURRENT: Connection timeout (event)
]]></error>
	</testcase>
</testsuite>
