<?xml version="1.0" encoding="UTF-8"?>
<testsuite name="tests.technix.TechnixTests-20220405100204" tests="6" file="tests/technix.py" time="0.012" timestamp="2022-04-05T10:02:16" failures="6" errors="0" skipped="0">
	<testcase classname="tests.technix.TechnixTests" name="test_WHEN_set_current_THEN_get_current_back_correctly" time="0.007" timestamp="2022-04-05T10:02:16" file="tests\technix.py" line="51">
		<failure type="AssertionError" message="Emulator (Technix) is not running"><![CDATA[Traceback (most recent call last):
  File "C:\Instrument\Apps\EPICS\support\technix\master\system_tests\tests\technix.py", line 44, in setUp
    self._lewis, self._ioc = get_running_lewis_and_ioc("Technix", DEVICE_PREFIX)
  File "C:\Instrument\Apps\EPICS\support\IocTestFramework\master\utils\testing.py", line 98, in get_running_lewis_and_ioc
    raise AssertionError("Emulator ({}) is not running".format(emulator_name))
AssertionError: Emulator (Technix) is not running
]]></failure>
	</testcase>
	<testcase classname="tests.technix.TechnixTests" name="test_WHEN_set_inhibit_to_active_THEN_inhibit_is_active" time="0.001" timestamp="2022-04-05T10:02:16" file="tests\technix.py" line="70">
		<failure type="AssertionError" message="Emulator (Technix) is not running"><![CDATA[Traceback (most recent call last):
  File "C:\Instrument\Apps\EPICS\support\technix\master\system_tests\tests\technix.py", line 44, in setUp
    self._lewis, self._ioc = get_running_lewis_and_ioc("Technix", DEVICE_PREFIX)
  File "C:\Instrument\Apps\EPICS\support\IocTestFramework\master\utils\testing.py", line 98, in get_running_lewis_and_ioc
    raise AssertionError("Emulator ({}) is not running".format(emulator_name))
AssertionError: Emulator (Technix) is not running
]]></failure>
	</testcase>
	<testcase classname="tests.technix.TechnixTests" name="test_WHEN_set_inhibit_to_idle_THEN_inhibit_is_idle" time="0.001" timestamp="2022-04-05T10:02:16" file="tests\technix.py" line="65">
		<failure type="AssertionError" message="Emulator (Technix) is not running"><![CDATA[Traceback (most recent call last):
  File "C:\Instrument\Apps\EPICS\support\technix\master\system_tests\tests\technix.py", line 44, in setUp
    self._lewis, self._ioc = get_running_lewis_and_ioc("Technix", DEVICE_PREFIX)
  File "C:\Instrument\Apps\EPICS\support\IocTestFramework\master\utils\testing.py", line 98, in get_running_lewis_and_ioc
    raise AssertionError("Emulator ({}) is not running".format(emulator_name))
AssertionError: Emulator (Technix) is not running
]]></failure>
	</testcase>
	<testcase classname="tests.technix.TechnixTests" name="test_WHEN_set_local_mode_THEN_mode_is_local" time="0.001" timestamp="2022-04-05T10:02:16" file="tests\technix.py" line="55">
		<failure type="AssertionError" message="Emulator (Technix) is not running"><![CDATA[Traceback (most recent call last):
  File "C:\Instrument\Apps\EPICS\support\technix\master\system_tests\tests\technix.py", line 44, in setUp
    self._lewis, self._ioc = get_running_lewis_and_ioc("Technix", DEVICE_PREFIX)
  File "C:\Instrument\Apps\EPICS\support\IocTestFramework\master\utils\testing.py", line 98, in get_running_lewis_and_ioc
    raise AssertionError("Emulator ({}) is not running".format(emulator_name))
AssertionError: Emulator (Technix) is not running
]]></failure>
	</testcase>
	<testcase classname="tests.technix.TechnixTests" name="test_WHEN_set_remote_mode_THEN_mode_is_remote" time="0.001" timestamp="2022-04-05T10:02:16" file="tests\technix.py" line="60">
		<failure type="AssertionError" message="Emulator (Technix) is not running"><![CDATA[Traceback (most recent call last):
  File "C:\Instrument\Apps\EPICS\support\technix\master\system_tests\tests\technix.py", line 44, in setUp
    self._lewis, self._ioc = get_running_lewis_and_ioc("Technix", DEVICE_PREFIX)
  File "C:\Instrument\Apps\EPICS\support\IocTestFramework\master\utils\testing.py", line 98, in get_running_lewis_and_ioc
    raise AssertionError("Emulator ({}) is not running".format(emulator_name))
AssertionError: Emulator (Technix) is not running
]]></failure>
	</testcase>
	<testcase classname="tests.technix.TechnixTests" name="test_WHEN_set_voltage_THEN_get_voltage_back_correctly" time="0.001" timestamp="2022-04-05T10:02:16" file="tests\technix.py" line="47">
		<failure type="AssertionError" message="Emulator (Technix) is not running"><![CDATA[Traceback (most recent call last):
  File "C:\Instrument\Apps\EPICS\support\technix\master\system_tests\tests\technix.py", line 44, in setUp
    self._lewis, self._ioc = get_running_lewis_and_ioc("Technix", DEVICE_PREFIX)
  File "C:\Instrument\Apps\EPICS\support\IocTestFramework\master\utils\testing.py", line 98, in get_running_lewis_and_ioc
    raise AssertionError("Emulator ({}) is not running".format(emulator_name))
AssertionError: Emulator (Technix) is not running
]]></failure>
	</testcase>
</testsuite>
