<?xml version="1.0" encoding="UTF-8"?>
<testsuite name="tests.technix.TechnixTests-20220523135937" tests="6" file="tests/technix.py" time="21.847" timestamp="2022-05-23T14:00:04" failures="2" errors="0" skipped="0">
	<testcase classname="tests.technix.TechnixTests" name="test_WHEN_set_inhibit_to_active_THEN_inhibit_is_active" time="1.109" timestamp="2022-05-23T13:59:52" file="tests\technix.py" line="78"/>
	<testcase classname="tests.technix.TechnixTests" name="test_WHEN_set_inhibit_to_idle_THEN_inhibit_is_idle" time="1.033" timestamp="2022-05-23T13:59:53" file="tests\technix.py" line="73"/>
	<testcase classname="tests.technix.TechnixTests" name="test_WHEN_set_local_mode_THEN_mode_is_local" time="1.130" timestamp="2022-05-23T13:59:54" file="tests\technix.py" line="63"/>
	<testcase classname="tests.technix.TechnixTests" name="test_WHEN_set_remote_mode_THEN_mode_is_remote" time="1.064" timestamp="2022-05-23T13:59:55" file="tests\technix.py" line="68"/>
	<testcase classname="tests.technix.TechnixTests" name="test_WHEN_set_current_THEN_get_current_back_correctly" time="8.509" timestamp="2022-05-23T13:59:51" file="tests\technix.py" line="55">
		<failure type="AssertionError" message="Expected PV, 'TE:NDW1799:TECHNIX_01:_CRAW.RVAL' to have value '4095' (type: 'int').
Final PV value was '0' (type: 'int')"><![CDATA[Traceback (most recent call last):
  File "C:\Instrument\Apps\EPICS\support\IocTestFramework\master\utils\testing.py", line 148, in wrapper
    return func(*args, **kwargs)
  File "C:\Instrument\Apps\EPICS\support\technix\master\system_tests\tests\technix.py", line 61, in test_WHEN_set_current_THEN_get_current_back_correctly
    self.ca.assert_that_pv_is("_CRAW.RVAL", 4095)
  File "C:\Instrument\Apps\EPICS\support\IocTestFramework\master\utils\channel_access.py", line 269, in assert_that_pv_is
    return self.assert_that_pv_value_causes_func_to_return_true(
  File "C:\Instrument\Apps\EPICS\support\IocTestFramework\master\utils\channel_access.py", line 248, in assert_that_pv_value_causes_func_to_return_true
    raise AssertionError(err)
AssertionError: Expected PV, 'TE:NDW1799:TECHNIX_01:_CRAW.RVAL' to have value '4095' (type: 'int').
Final PV value was '0' (type: 'int')
]]></failure>
	</testcase>
	<testcase classname="tests.technix.TechnixTests" name="test_WHEN_set_voltage_THEN_get_voltage_back_correctly" time="9.001" timestamp="2022-05-23T14:00:04" file="tests\technix.py" line="47">
		<failure type="AssertionError" message="Expected PV 'TE:NDW1799:TECHNIX_01:_VRAW.RVAL' value to be equal to '4095' (type: 'int') (tolerance: '0.0' (type: 'float'))
Final PV value was '0' (type: 'int')"><![CDATA[Traceback (most recent call last):
  File "C:\Instrument\Apps\EPICS\support\IocTestFramework\master\utils\testing.py", line 148, in wrapper
    return func(*args, **kwargs)
  File "C:\Instrument\Apps\EPICS\support\technix\master\system_tests\tests\technix.py", line 53, in test_WHEN_set_voltage_THEN_get_voltage_back_correctly
    self.ca.assert_that_pv_is_number("_VRAW.RVAL", 4095)
  File "C:\Instrument\Apps\EPICS\support\IocTestFramework\master\utils\channel_access.py", line 380, in assert_that_pv_is_number
    return self.assert_that_pv_value_causes_func_to_return_true(
  File "C:\Instrument\Apps\EPICS\support\IocTestFramework\master\utils\channel_access.py", line 248, in assert_that_pv_value_causes_func_to_return_true
    raise AssertionError(err)
AssertionError: Expected PV 'TE:NDW1799:TECHNIX_01:_VRAW.RVAL' value to be equal to '4095' (type: 'int') (tolerance: '0.0' (type: 'float'))
Final PV value was '0' (type: 'int')
]]></failure>
	</testcase>
</testsuite>
